// Jest Snapshot v1, https://goo.gl/fbAQLP

exports[`Validating rule docs return-await.mdx code examples ESLint output 1`] = `
"Incorrect
Options: "in-try-catch"

async function invalidInTryCatch1() {
  try {
    return Promise.reject('try');
           ~~~~~~~~~~~~~~~~~~~~~ Returning an awaited promise is required in this context.
  } catch (e) {
    // Doesn't execute due to missing await.
  }
}

async function invalidInTryCatch2() {
  try {
    throw new Error('error');
  } catch (e) {
    // Unnecessary await; rejections here don't impact control flow.
    return await Promise.reject('catch');
           ~~~~~~~~~~~~~~~~~~~~~~~~~~~~~ Returning an awaited promise is not allowed in this context.
  }
}

// Prints 'starting async work', 'cleanup', 'async work done'.
async function invalidInTryCatch3() {
  async function doAsyncWork(): Promise<void> {
    console.log('starting async work');
    await new Promise(resolve => setTimeout(resolve, 1000));
    console.log('async work done');
  }

  try {
    throw new Error('error');
  } catch (e) {
    // Missing await.
    return doAsyncWork();
           ~~~~~~~~~~~~~ Returning an awaited promise is required in this context.
  } finally {
    console.log('cleanup');
  }
}

async function invalidInTryCatch4() {
  try {
    throw new Error('error');
  } catch (e) {
    throw new Error('error2');
  } finally {
    // Unnecessary await; rejections here don't impact control flow.
    return await Promise.reject('finally');
           ~~~~~~~~~~~~~~~~~~~~~~~~~~~~~~~ Returning an awaited promise is not allowed in this context.
  }
}

async function invalidInTryCatch5() {
  return await Promise.resolve('try');
         ~~~~~~~~~~~~~~~~~~~~~~~~~~~~ Returning an awaited promise is not allowed in this context.
}

async function invalidInTryCatch6() {
  return await 'value';
         ~~~~~~~~~~~~~ Returning an awaited value that is not a promise is not allowed.
}
"
`;

exports[`Validating rule docs return-await.mdx code examples ESLint output 2`] = `
"Correct
Options: "in-try-catch"

async function validInTryCatch1() {
  try {
    return await Promise.reject('try');
  } catch (e) {
    // Executes as expected.
  }
}

async function validInTryCatch2() {
  try {
    throw new Error('error');
  } catch (e) {
    return Promise.reject('catch');
  }
}

// Prints 'starting async work', 'async work done', 'cleanup'.
async function validInTryCatch3() {
  async function doAsyncWork(): Promise<void> {
    console.log('starting async work');
    await new Promise(resolve => setTimeout(resolve, 1000));
    console.log('async work done');
  }

  try {
    throw new Error('error');
  } catch (e) {
    return await doAsyncWork();
  } finally {
    console.log('cleanup');
  }
}

async function validInTryCatch4() {
  try {
    throw new Error('error');
  } catch (e) {
    throw new Error('error2');
  } finally {
    return Promise.reject('finally');
  }
}

async function validInTryCatch5() {
  return Promise.resolve('try');
}

async function validInTryCatch6() {
  return 'value';
}
"
`;

exports[`Validating rule docs return-await.mdx code examples ESLint output 3`] = `
"Incorrect
Options: "always"

async function invalidAlways1() {
  try {
    return Promise.resolve('try');
           ~~~~~~~~~~~~~~~~~~~~~~ Returning an awaited promise is required in this context.
  } catch (e) {}
}

async function invalidAlways2() {
  return Promise.resolve('try');
         ~~~~~~~~~~~~~~~~~~~~~~ Returning an awaited promise is required in this context.
}

async function invalidAlways3() {
  return await 'value';
         ~~~~~~~~~~~~~ Returning an awaited value that is not a promise is not allowed.
}
"
`;

exports[`Validating rule docs return-await.mdx code examples ESLint output 4`] = `
"Correct
Options: "always"

async function validAlways1() {
  try {
    return await Promise.resolve('try');
  } catch (e) {}
}

async function validAlways2() {
  return await Promise.resolve('try');
}

async function validAlways3() {
  return 'value';
}
"
`;

exports[`Validating rule docs return-await.mdx code examples ESLint output 5`] = `
"Incorrect
Options: "never"

async function invalidNever1() {
  try {
    return await Promise.resolve('try');
           ~~~~~~~~~~~~~~~~~~~~~~~~~~~~ Returning an awaited promise is not allowed in this context.
  } catch (e) {}
}

async function invalidNever2() {
  return await Promise.resolve('try');
         ~~~~~~~~~~~~~~~~~~~~~~~~~~~~ Returning an awaited promise is not allowed in this context.
}

async function invalidNever3() {
  return await 'value';
         ~~~~~~~~~~~~~ Returning an awaited value that is not a promise is not allowed.
}
"
`;

exports[`Validating rule docs return-await.mdx code examples ESLint output 6`] = `
"Correct
Options: "never"

async function validNever1() {
  try {
    return Promise.resolve('try');
  } catch (e) {}
}

async function validNever2() {
  return Promise.resolve('try');
}

async function validNever3() {
  return 'value';
}
"
`;
